Workbook

Sheet 📋 Instructions
A1: AI MASTERY — ROI CALCULATOR
A2: AI-Powered Process Automation for Business Operations | Participant Tool
A4: HOW TO USE THIS TOOL
A5: STEP 1 | B5: Go to the '🧮 ROI Calculator' sheet.
A6: STEP 2 | B6: Fill in only the BLUE cells — these are your input fields. Do NOT change formula cells (black text).
A7: STEP 3 | B7: Enter your process data in Section A (Current State) and Section B (AI Investment).
A8: STEP 4 | B8: All ROI results in Section C calculate automatically — no manual entry needed.
A9: STEP 5 | B9: Review the '📊 Benchmark Data' sheet to compare your results against industry benchmarks.
A10: STEP 6 | B10: Copy your key results to the '📄 Executive Summary' sheet to present to management.
A12: COLOUR LEGEND
A13: Blue cells | B13: Your INPUT — fill these in
A14: Black cells | B14: FORMULA — calculated automatically, do not edit
A15: Green cells | B15: RESULT — your ROI output
A16: Orange cells | B16: WARNING / check your data
A18: Developed by: Fakhrul Syahmi | Data Consultant & Certified Trainer | mufasyahcons@gmail.com | © 2026

Sheet 🧮 ROI Calculator
A1: 🧮 AI AUTOMATION ROI CALCULATOR
A2: Fill in BLUE cells only | All calculations update automatically | AI Mastery Training Programme
A4: SECTION A — CURRENT STATE (Manual Process Costs)
A5: INPUT FIELD | F5: YOUR INPUT | H5: NOTES / GUIDE
A6: Process Name | H6: Name the process you are automating
A7: Department / Business Unit | H7: e.g. Finance, HR, Procurement
A8: Number of staff currently performing this process | H8: Headcount involved in this task
A9: Average staff hourly cost (RM) | H9: Include salary + benefits + overhead
A10: Manual processing time per transaction (minutes) | H10: Time from start to end of one task
A11: Monthly transaction volume | H11: How many times this task occurs per month
A12: Current error / rework rate (%) | H12: Percentage of transactions with errors
A13: Average cost to fix one error (RM) | H13: Time + resource cost per error correction
A14: Monthly direct costs (printing, storage, etc. RM) | H14: Non-labour direct costs
A15: Time AI takes per transaction (minutes, estimated) | H15: Estimated after automation (typical: 2–5 mins)
A17: SECTION A — CALCULATED CURRENT COSTS (Auto)
A18: Monthly staff hours on this process | E18: =IFERROR(F10*F11/60, 0) -> 0 | F18: hrs/month | G18: =IFERROR(F10*F11/60*F8, 0) -> 0 | H18: RM/month
A19: Monthly labour cost of this process | E19: =IFERROR(F10*F11/60, 0) -> 0 | F19: hrs | G19: =IFERROR(F10*F11/60*F9, 0) -> 0 | H19: RM
A20: Monthly error / rework cost | E20: =IFERROR(F11*F12/100, 0) -> 0 | F20: errors/month | G20: =IFERROR(F11*F12/100*F13, 0) -> 0 | H20: RM/month
A21: Total monthly direct cost | G21: =IFERROR(F19+F20+F14, 0) -> 0 | H21: RM/month
A22: TOTAL ANNUAL CURRENT COST | G22: =IFERROR(F21*12, 0) -> 0 | H22: RM/year
A24: SECTION B — AI INVESTMENT COSTS
A25: AI Platform / Tool licence cost (RM/year) | H25: Annual software subscription fee
A26: Implementation & configuration cost (one-time, RM) | H26: Vendor setup, integration, testing
A27: Staff training cost (one-time, RM) | H27: Internal training and change management
A28: Annual maintenance & support cost (RM/year) | H28: Ongoing IT support and platform updates
A29: Other Year 1 costs (RM) | H29: Hardware, consultancy, or other one-time items
A30: TOTAL YEAR 1 INVESTMENT (RM) | F30: =IFERROR(F25+F26+F27+F28+F29, 0) -> 0
A31: Ongoing Annual Cost from Year 2 (RM) | F31: =IFERROR(F25+F28, 0) -> 0
A33: SECTION C — ROI RESULTS (Calculated Automatically)
A34: Annual labour cost saving (RM) | F34: =IFERROR((F10-F15)*F11*12/60*F9, 0) -> 0 | H34: Hours saved per year × hourly rate
A35: Annual error / rework saving (RM) | F35: =IFERROR(F11*F12/100*F13*12, 0) -> 0 | H35: Errors eliminated × cost per error × 12 months
A36: Annual direct cost saving (RM) | F36: =IFERROR(F14*12, 0) -> 0 | H36: Printing, storage & other direct costs saved
A37: TOTAL ANNUAL SAVING (RM) | F37: =IFERROR(G34+G35+G36, 0) -> 0 | H37: Sum of all annual savings
A38: Net Year 1 Saving (RM) | F38: =IFERROR(G37-F30, 0) -> 0 | H38: Total savings minus total Year 1 investment
A39: Net Year 2+ Annual Saving (RM) | F39: =IFERROR(G37-F31, 0) -> 0 | H39: Total savings minus ongoing annual cost
A40: Year 1 ROI (%) | F40: =IFERROR(IF(F30=0,0,(G37-F30)/F30), 0) -> 0 | H40: Net Saving ÷ Investment × 100
A41: Payback Period (months) | F41: =IFERROR(IF(G37=0,0,F30/(G37/12)), 0) -> 0 | H41: Investment ÷ Monthly saving
A42: 3-Year Net Value (RM) | F42: =IFERROR(G37*3-F30-(F31*2), 0) -> 0 | H42: 3 years of savings minus all costs
A44: SECTION D — PROJECT HEALTH INDICATORS
A45: ROI Status | C45: =IFERROR(IF(G40>=1,"🟢 STRONG ROI — Proceed with confidence",IF(G40>=0.5,"🟡 MODERATE ROI — Refine your cost estimates",IF(G40>0,"🔴 LOW ROI — Review tool selection or scope","⚪ Enter data above to calculate"))),"⚪ Enter data above") -> ⚪ Enter data above to calculate | H45: Target: ROI > 100% (>1.0x) for Year 1 approval
...

Sheet 📊 Benchmark Data
A1: 📊 AI AUTOMATION INDUSTRY BENCHMARKS
A2: Reference data to compare your ROI results against industry averages. Source: Gartner, McKinsey, Forrester Research (2024)
A4: BENCHMARK ROI BY AUTOMATION USE CASE
A5: Use Case | B5: Dept | C5: Avg Time Saving | D5: Avg Error Reduction | E5: Typical ROI Year 1 | F5: Avg Payback | G5: Complexity | H5: Recommended Tool
A6: Invoice Processing | B6: Finance | C6: 70–80% | D6: 90–95% | E6: 120–180% | F6: 4–6 months | G6: Low | H6: Power Automate / UiPath
A7: Email Sorting & Routing | B7: All depts | C7: 60–75% | D7: 85–95% | E7: 100–150% | F7: 3–5 months | G7: Low | H7: Power Automate / Copilot
A8: Employee Onboarding | B8: HR | C8: 65–75% | D8: 80–90% | E8: 90–130% | F8: 5–8 months | G8: Medium | H8: Power Automate / UiPath
A9: Payroll Processing | B9: HR / Finance | C9: 75–85% | D9: 95–99% | E9: 110–160% | F9: 4–7 months | G9: Medium | H9: UiPath / RPA tools
A10: Report Generation | B10: Analytics | C10: 80–90% | D10: 98–100% | E10: 130–200% | F10: 3–5 months | G10: Low | H10: Power Automate / Excel
A11: Purchase Order Processing | B11: Procurement | C11: 60–70% | D11: 80–90% | E11: 100–140% | F11: 5–8 months | G11: Medium | H11: Power Automate / SAP
A12: Customer Support (chatbot) | B12: Customer Svc | C12: 40–60% | D12: 70–85% | E12: 80–120% | F12: 6–10 months | G12: Medium | H12: Copilot Studio / Azure Bot
A13: Data Entry & Validation | B13: All depts | C13: 85–95% | D13: 95–99% | E13: 150–250% | F13: 2–4 months | G13: Low | H13: Power Automate / RPA
A14: Compliance Reporting | B14: Legal / Finance | C14: 70–80% | D14: 90–98% | E14: 100–150% | F14: 5–9 months | G14: High | H14: UiPath / Power Platform
A15: Demand Forecasting | B15: Operations | C15: 50–65% | D15: 60–80% | E15: 80–120% | F15: 6–12 months | G15: High | H15: Azure ML / Power BI
A18: YOUR RESULTS vs BENCHMARK (Links from Calculator)
A19: Metric | B19: Your Result | C19: Industry Benchmark | D19: Status
A20: Year 1 ROI | B20: ='🧮 ROI Calculator'!G40 -> 0 | C20: 100–180% | D20: =IFERROR(IF('🧮 ROI Calculator'!G40>=1,"🟢 Above benchmark",IF('🧮 ROI Calculator'!G40>=0.5,"🟡 Near benchmark","🔴 Below benchmark")),"⚪ No data") -> 🔴 Below benchmark
A21: Payback Period | B21: ='🧮 ROI Calculator'!G41 -> 0 | C21: 4–8 months | D21: =IFERROR(IF('🧮 ROI Calculator'!G41=0,"⚪ No data",IF('🧮 ROI Calculator'!G41<=8,"🟢 At or above benchmark",IF('🧮 ROI Calculator'!G41<=12,"🟡 Near benchmark","🔴 Below benchmark"))),"⚪ No data") -> ⚪ No data
A22: Annual Savings | B22: ='🧮 ROI Calculator'!G37 -> 0 | C22: RM 50K–200K typical | D22: =IFERROR(IF('🧮 ROI Calculator'!G37=0,"⚪ No data","ℹ️ Compare to your project scale"),"⚪ No data") -> ⚪ No data
A23: 3-Year Net Value | B23: ='🧮 ROI Calculator'!G42 -> 0 | C23: RM 100K–500K typical | D23: =IFERROR(IF('🧮 ROI Calculator'!G42=0,"⚪ No data","ℹ️ Compare to your project scale"),"⚪ No data") -> ⚪ No data

Sheet 📄 Executive Summary
A1: 📄 AI AUTOMATION BUSINESS CASE — EXECUTIVE SUMMARY
A2: Auto-populated from ROI Calculator | Print or share this sheet with management
A4: PROJECT OVERVIEW
A5: Process Name | C5: ='🧮 ROI Calculator'!F6 -> 0
A6: Department | C6: ='🧮 ROI Calculator'!F7 -> 0
A7: Prepared by
A8: Date | C8: =TODAY() -> 46155
A10: KEY FINANCIAL RESULTS
A11: Total Annual Savings | D11: ='🧮 ROI Calculator'!G37 -> 0
A12: Year 1 Investment | D12: ='🧮 ROI Calculator'!F30 -> 0
A13: Net Year 1 Saving | D13: ='🧮 ROI Calculator'!G38 -> 0
A14: Year 1 ROI | D14: ='🧮 ROI Calculator'!G40 -> 0
A15: Payback Period | D15: ='🧮 ROI Calculator'!G41 -> 0
A16: 3-Year Net Value | D16: ='🧮 ROI Calculator'!G42 -> 0
A18: RECOMMENDATION
A19: ℹ️ Complete the ROI Calculator to generate a recommendation.
A21: Fakhrul Syahmi | Data Consultant & Certified Trainer | mufasyahcons@gmail.com | © 2026
